Workbook

Sheet Key Assumptions RJPP
A1: Key Assumptions RJPP 2026-2030 PT ABC Energy
A2: Parameter | B2: Year 2026 | C2: Year 2027 | D2: Year 2028 | E2: Year 2029 | F2: Year 2030
A3: Harga Listrik USD/kwH | B3: 0.08 | C3: 0.082 | D3: 0.085 | E3: 0.087 | F3: 0.09
A4: Kurs USD/IDR | B4: 16500 | C4: 17000 | D4: 17500 | E4: 18000 | F4: 18500

Sheet Operasional
A1: Volume Kapasitas Terpasang dan Produksi Listrik New Energy
A2: Kaspasitas Terpasang (MW) | B2: Year 2026 | C2: Year 2027 | D2: Year 2028 | E2: Year 2029 | F2: Year 2030
A3: Geothermal | B3: 880 | C3: 960 | D3: 1300 | E3: 1400 | F3: 1600
A4: PLTS | B4: 160 | C4: 280 | D4: 320 | E4: 480 | F4: 500
A5: PLTSa | B5: 50 | C5: 50 | D5: 50 | E5: 50 | F5: 50
A6: Total Kapasitas Terpasang (MW) | B6: =SUM(B3:B5) -> 1090 | C6: =SUM(C3:C5) -> 1290 | D6: =SUM(D3:D5) -> 1670 | E6: =SUM(E3:E5) -> 1930 | F6: =SUM(F3:F5) -> 2150
A8: Produksi Listrik (GWh) | B8: Year 2026 | C8: Year 2027 | D8: Year 2028 | E8: Year 2029 | F8: Year 2030
A9: Geothermal | B9: 5280 | C9: 5760 | D9: 9100 | E9: 9800 | F9: 11200
A10: PLTS | B10: 40 | C10: 70 | D10: 160 | E10: 240 | F10: 250
A11: Other New Energy | B11: 7 | C11: 42 | D11: 43 | E11: 44 | F11: 45
A12: Total Produksi Listrik (GWh) | B12: =SUM(B9:B11) -> 5327 | C12: =SUM(C9:C11) -> 5872 | D12: =SUM(D9:D11) -> 9303 | E12: =SUM(E9:E11) -> 10084 | F12: =SUM(F9:F11) -> 11495
A14: Total Produksi Listrik (kWh) | B14: =B12*1000000 -> 5327000000 | C14: =C12*1000000 -> 5872000000 | D14: =D12*1000000 -> 9303000000 | E14: =E12*1000000 -> 10084000000 | F14: =F12*1000000 -> 11495000000

Sheet Finansial
A1: Income Statement
A3: All figures in USD thousands unless stated | C3: Year 2026 | D3: Year 2027 | E3: Year 2028 | F3: Year 2029 | G3: Year 2030
A5: Revenues | C5: =(Operasional!B14*'Key Assumptions RJPP'!B3)/1000 -> 426160 | D5: =(Operasional!C14*'Key Assumptions RJPP'!C3)/1000 -> 481504 | E5: =(Operasional!D14*'Key Assumptions RJPP'!D3)/1000 -> 790755 | F5: =(Operasional!E14*'Key Assumptions RJPP'!E3)/1000 -> 877308 | G5: =(Operasional!F14*'Key Assumptions RJPP'!F3)/1000 -> 1034550
A6: Cost of Goods Sold | C6: -191772 | D6: -211862 | E6: -332117 | F6: -359696 | G6: -413820
A7: Gross Profit | C7: =SUM(C5:C6) -> 234388 | D7: =SUM(D5:D6) -> 269642 | E7: =SUM(E5:E6) -> 458638 | F7: =SUM(F5:F6) -> 517612 | G7: =SUM(G5:G6) -> 620730
A9: SG&A | C9: -34093 | D9: -38520 | E9: -63260 | F9: -70185 | G9: -82764
A10: EBITDA | C10: =SUM(C7:C9) -> 200295 | D10: =SUM(D7:D9) -> 231122 | E10: =SUM(E7:E9) -> 395378 | F10: =SUM(F7:F9) -> 447427 | G10: =SUM(G7:G9) -> 537966
A12: DD&A | C12: -42616 | D12: -48150 | E12: -79076 | F12: -87731 | G12: -103455
A13: EBIT (Operating Profit) | C13: =SUM(C10:C12) -> 157679 | D13: =SUM(D10:D12) -> 182972 | E13: =SUM(E10:E12) -> 316302 | F13: =SUM(F10:F12) -> 359696 | G13: =SUM(G10:G12) -> 434511
A15: Interest Expense | C15: -12000 | D15: -12000 | E15: -12000 | F15: -12000 | G15: -12000
A16: Earnings Before Taxes | C16: =SUM(C13:C15) -> 145679 | D16: =SUM(D13:D15) -> 170972 | E16: =SUM(E13:E15) -> 304302 | F16: =SUM(F13:F15) -> 347696 | G16: =SUM(G13:G15) -> 422511
A18: Taxes (22%) | C18: =-(0.22*C16) -> -32049.38 | D18: =-(0.22*D16) -> -37613.84 | E18: =-(0.22*E16) -> -66946.44 | F18: =-(0.22*F16) -> -76493.12 | G18: =-(0.22*G16) -> -92952.42
A19: Net Income | C19: =SUM(C16:C18) -> 113629.62 | D19: =SUM(D16:D18) -> 133358.16 | E19: =SUM(E16:E18) -> 237355.56 | F19: =SUM(F16:F18) -> 271202.88 | G19: =SUM(G16:G18) -> 329558.58
A21: Common Dividends | C21: 4312 | D21: 4209 | E21: 2930.9751 | F21: =#REF!*F19 -> #REF! | G21: =#REF!*G19 -> #REF! | I21: Alternative: Forecast Share Count and Dividends per Share
A25: Balance Sheet
A27: All figures in USD thousands unless stated | C27: =+#REF! -> #REF! | D27: =+#REF! -> #REF! | E27: =+#REF! -> #REF! | F27: =+#REF! -> #REF! | G27: =+#REF! -> #REF!
A29: ASSETS
A30: Cash
A31: Trade and Other Receivables | C31: 12685 | D31: 14074 | E31: 14721.209 | F31: =F103 -> #REF! | G31: =G103 -> #REF!
A32: Inventories | C32: 7168 | D32: 7691 | E32: 8036.3319 | F32: =F104 -> #REF! | G32: =G104 -> #REF!
A33: Total Current Assets | C33: =SUM(C30:C32) -> 19853 | D33: =SUM(D30:D32) -> 21765 | E33: =SUM(E30:E32) -> 22757.54 | F33: =SUM(F30:F32) -> #REF! | G33: =SUM(G30:G32) -> #REF!
A35: Property Plant and Equipment | C35: 19263 | D35: 20371 | E35: 21175 | F35: =F123 -> #REF! | G35: =G123 -> #REF!
A37: TOTAL ASSETS | C37: =SUM(C35,C33) -> 39116 | D37: =SUM(D35,D33) -> 42136 | E37: =SUM(E35,E33) -> 43932.54 | F37: =SUM(F35,F33) -> #REF! | G37: =SUM(G35,G33) -> #REF!
A39: LIABILITIES
A40: Trade and Other Payables | C40: 10001 | D40: 10504 | E40: 11077.106 | F40: =F105 -> #REF! | G40: =G105 -> #REF!
A41: Income Taxes Payable | C41: 1088 | D41: 894 | E41: 581 | F41: =F106 -> #REF! | G41: =G106 -> #REF!
A42: Total Current Liabilities | C42: =SUM(C40:C41) -> 11089 | D42: =SUM(D40:D41) -> 11398 | E42: =SUM(E40:E41) -> 11658.106 | F42: =SUM(F40:F41) -> #REF! | G42: =SUM(G40:G41) -> #REF!
A44: Long-Term Debt | C44: 20000 | D44: 20000 | E44: 20000 | F44: =#REF! -> #REF! | G44: =#REF! -> #REF!
A45: Total Liabilities | C45: =SUM(C42,C44) -> 31089 | D45: =SUM(D42,D44) -> 31398 | E45: =SUM(E42,E44) -> 31658.106 | F45: =SUM(F42,F44) -> #REF! | G45: =SUM(G42,G44) -> #REF!
A47: EQUITY
A48: Common Stock and Additional Paid-In Capital | C48: 7627 | D48: 7627 | E48: 7627 | F48: =F144 -> #REF! | G48: =G144 -> #REF!
A49: Retained Earnings | C49: 5689 | D49: 9029 | E49: 14806.218 | F49: =F153 -> #REF! | G49: =G153 -> #REF!
A50: Total Shareholders' Equity | C50: =SUM(C48:C49) -> 13316 | D50: =SUM(D48:D49) -> 16656 | E50: =SUM(E48:E49) -> 22433.218 | F50: =SUM(F48:F49) -> #REF! | G50: =SUM(G48:G49) -> #REF!
A52: Total Liabilities & Equity | C52: =SUM(C45,C50) -> 44405 | D52: =SUM(D45,D50) -> 48054 | E52: =SUM(E45,E50) -> 54091.324 | F52: =SUM(F45,F50) -> #REF! | G52: =SUM(G45,G50) -> #REF!
A54: Balance Sheet Check | C54: =C52=C37 -> FALSE | D54: =D52=D37 -> FALSE | E54: =E52=E37 -> FALSE | F54: =F52=F37 -> #REF! | G54: =G52=G37 -> #REF!
A58: Cash Flow Statement
A60: All figures in USD thousands unless stated | C60: =+#REF! -> #REF! | D60: =+#REF! -> #REF! | E60: =+#REF! -> #REF! | F60: =+#REF! -> #REF! | G60: =+#REF! -> #REF!
A62: Cash Flows from Operating Activities
A63: Net Income
A64: Depreciation
...
