Workbook

Sheet README
A1: README — PT ABC Energy · RJPP 2026–2030 · Hilir (Downstream) · Middle Scenario
A2: Field | B2: Details
A3: Purpose | B3: Knowledge source for the Microsoft 365 Copilot agent "3C - RJPP Analyst" (SPPU SPARK Copilot training). All figures are dummy data for training purposes only.
A4: Company | B4: PT ABC Energy
A5: Plan | B5: RJPP 2026–2030 (Rencana Jangka Panjang Perusahaan — company long-term plan)
A6: Business line | B6: Hilir (Downstream — Refining & Marketing)
A7: Scenario | B7: Middle
A8: Currency & units | B8: Financials in USD thousands. Operational volumes in Juta BBL (million barrels); the unit is stated on every row. Prices in USD/bbl; exchange rate in IDR per USD.
A9: Source | B9: Refined from 4_BL_Hilir_RJPP_2026_2030_MiddleScenario_ABCEnergy_v1.xlsx
A10: Color legend | B10: Blue font = input value taken from the source; black font = formula; green font = link to another sheet; light-green fill = total / key row.
A11: Sheet map
A12: Sheet map: README | B12: This sheet — purpose, context, sheet map, changes from the source file and data notes.
A13: Sheet map: Key Assumptions | B13: Price assumptions (USD/bbl) for crude oil, intermedia and each product line, plus the USD/IDR exchange rate, 2026–2030.
A14: Sheet map: Operasional | B14: Refinery input, refinery output and sales volumes (Juta BBL) in five groups, each ending with a live total row, 2026–2030.
A15: Sheet map: Finansial | B15: Income statement (USD thousands) from Revenues to Net Income, EBITDA and net margins, the corporate tax rate input and CAPEX, 2026–2030.
A16: Sheet map: Data | B16: Flat Excel Table "Data_Hilir": one row per metric from Key Assumptions, Operasional and Finansial, linked by formulas, for search and scripts.
A17: Changes from the source file
A18: Change 1 | B18: Fixed the title typo "Pejualan" → "Penjualan".
A19: Change 2 | B19: Removed a stray unlabeled value (0.159) that sat beside the Gasoline sales row.
A20: Change 3 | B20: Totals, subtotals and revenue are now live formulas.
A21: Change 4 | B21: The balance sheet and cash-flow sections of the source were removed because they contained broken references (#REF!) and template placeholder values.
A22: Data notes / to confirm
A23: CAPEX | B23: CAPEX is 0 in every year in the source model — kept as stated, to be confirmed.
A24: Revenue method | B24: Revenues (USD thousands) = Σ product sales volume (Juta BBL) × product price (USD/bbl) × 1000, for Gasoline, Gasoil, Other Fuel, LPG, Petrokimia and Other Non-Fuel.
A25: Tax method | B25: Taxes = −Earnings Before Taxes × corporate tax rate (22%, input on the Finansial sheet).

Sheet Key Assumptions
A1: Key Assumptions — Prices & Exchange Rate, Hilir RJPP 2026–2030 (Middle Scenario)
A2: Parameter | B2: Unit | C2: 2026 | D2: 2027 | E2: 2028 | F2: 2029 | G2: 2030
A3: Oil Price (crude) | B3: USD/bbl | C3: 70 | D3: 75 | E3: 80 | F3: 85 | G3: 90
A4: Intermedia + Others | B4: USD/bbl | C4: 60 | D4: 65 | E4: 70 | F4: 75 | G4: 80
A5: Gasoline | B5: USD/bbl | C5: 80 | D5: 86 | E5: 92 | F5: 98 | G5: 104
A6: Gasoil | B6: USD/bbl | C6: 85 | D6: 92 | E6: 99 | F6: 106 | G6: 113
A7: Other Fuel | B7: USD/bbl | C7: 75 | D7: 80 | E7: 85 | F7: 90 | G7: 95
A8: LPG | B8: USD/bbl | C8: 70 | D8: 75 | E8: 80 | F8: 85 | G8: 90
A9: Petrokimia | B9: USD/bbl | C9: 95 | D9: 100 | E9: 105 | F9: 110 | G9: 115
A10: Other Non-Fuel | B10: USD/bbl | C10: 85 | D10: 90 | E10: 95 | F10: 100 | G10: 105
A11: Exchange rate USD/IDR | B11: IDR per USD | C11: 16500 | D11: 17000 | E11: 17500 | F11: 18000 | G11: 18500
A13: Note: blue figures are inputs from the source model; product prices feed Revenues on the Finansial sheet.

Sheet Operasional
A1: Operasional — Refinery Input, Output & Penjualan (Sales) Volumes, Hilir RJPP 2026–2030 (Middle Scenario)
A2: Metric | B2: Unit | C2: 2026 | D2: 2027 | E2: 2028 | F2: 2029 | G2: 2030
A3: Refinery input (Input Kilang)
A4: Crude Oil | B4: Juta BBL | C4: 326.84211 | D4: 345.78947 | E4: 364.73684 | F4: 383.68421 | G4: 402.63158
A5: Intermedia + Others | B5: Juta BBL | C5: 36.315789 | D5: 38.421053 | E5: 40.526316 | F5: 42.631579 | G5: 44.736842
A6: Total Input Kilang | B6: Juta BBL | C6: =SUM(C4:C5) -> 363.15789 | D6: =SUM(D4:D5) -> 384.21053 | E6: =SUM(E4:E5) -> 405.26316 | F6: =SUM(F4:F5) -> 426.31579 | G6: =SUM(G4:G5) -> 447.36842
A8: Refinery output (Output Kilang)
A9: BBM | B9: Juta BBL | C9: 300 | D9: 315 | E9: 330 | F9: 345 | G9: 360
A10: LPG | B10: Juta BBL | C10: 10 | D10: 12 | E10: 14 | F10: 16 | G10: 18
A11: Non-BBM | B11: Juta BBL | C11: 35 | D11: 38 | E11: 41 | F11: 44 | G11: 47
A12: Total Output Kilang | B12: Juta BBL | C12: =SUM(C9:C11) -> 345 | D12: =SUM(D9:D11) -> 365 | E12: =SUM(E9:E11) -> 385 | F12: =SUM(F9:F11) -> 405 | G12: =SUM(G9:G11) -> 425
A14: Fuel sales (Penjualan BBM)
A15: Gasoline | B15: Juta BBL | C15: 150 | D15: 157.5 | E15: 165 | F15: 172.5 | G15: 180
A16: Gasoil | B16: Juta BBL | C16: 90 | D16: 94.5 | E16: 99 | F16: 103.5 | G16: 108
A17: Other Fuel | B17: Juta BBL | C17: 60 | D17: 63 | E17: 66 | F17: 69 | G17: 72
A18: Total Penjualan BBM | B18: Juta BBL | C18: =SUM(C15:C17) -> 300 | D18: =SUM(D15:D17) -> 315 | E18: =SUM(E15:E17) -> 330 | F18: =SUM(F15:F17) -> 345 | G18: =SUM(G15:G17) -> 360
A20: LPG sales (Penjualan LPG)
A21: LPG | B21: Juta BBL | C21: 10 | D21: 12 | E21: 14 | F21: 16 | G21: 18
A22: Total Penjualan LPG | B22: Juta BBL | C22: =SUM(C21:C21) -> 10 | D22: =SUM(D21:D21) -> 12 | E22: =SUM(E21:E21) -> 14 | F22: =SUM(F21:F21) -> 16 | G22: =SUM(G21:G21) -> 18
A24: Non-fuel sales (Penjualan Non-BBM)
A25: Petrokimia | B25: Juta BBL | C25: 28 | D25: 30.4 | E25: 32.8 | F25: 35.2 | G25: 37.6
A26: Other Non-Fuel | B26: Juta BBL | C26: 7 | D26: 7.6 | E26: 8.2 | F26: 8.8 | G26: 9.4
A27: Total Penjualan Non-BBM | B27: Juta BBL | C27: =SUM(C25:C26) -> 35 | D27: =SUM(D25:D26) -> 38 | E27: =SUM(E25:E26) -> 41 | F27: =SUM(F25:F26) -> 44 | G27: =SUM(G25:G26) -> 47

Sheet Finansial
A1: Finansial — Income Statement, Hilir RJPP 2026–2030 (Middle Scenario), USD thousands
A2: Assumptions
A3: Corporate tax rate | B3: % | C3: 0.22
A5: Line item | B5: Unit | C5: 2026 | D5: 2027 | E5: 2028 | F5: 2029 | G5: 2030
A6: Revenues | B6: USD thousands | C6: =(Operasional!C15*'Key Assumptions'!C5+Operasional!C16*'Key Assumptions'!C6+Operasional!C17*'Key Assumptions'!C7+Operasional!C21*'Key Assumptions'!C8+Operasional!C25*'Key Assumptions'!C9+Operasional!C26*'Key Assumptions'!C10)*1000 -> 28105000 | D6: =(Operasional!D15*'Key Assumptions'!D5+Operasional!D16*'Key Assumptions'!D6+Operasional!D17*'Key Assumptions'!D7+Operasional!D21*'Key Assumptions'!D8+Operasional!D25*'Key Assumptions'!D9+Operasional!D26*'Key Assumptions'!D10)*1000 -> 31903000 | E6: =(Operasional!E15*'Key Assumptions'!E5+Operasional!E16*'Key Assumptions'!E6+Operasional!E17*'Key Assumptions'!E7+Operasional!E21*'Key Assumptions'!E8+Operasional!E25*'Key Assumptions'!E9+Operasional!E26*'Key Assumptions'!E10)*1000 -> 35934000 | F6: =(Operasional!F15*'Key Assumptions'!F5+Operasional!F16*'Key Assumptions'!F6+Operasional!F17*'Key Assumptions'!F7+Operasional!F21*'Key Assumptions'!F8+Operasional!F25*'Key Assumptions'!F9+Operasional!F26*'Key Assumptions'!F10)*1000 -> 40198000 | G6: =(Operasional!G15*'Key Assumptions'!G5+Operasional!G16*'Key Assumptions'!G6+Operasional!G17*'Key Assumptions'!G7+Operasional!G21*'Key Assumptions'!G8+Operasional!G25*'Key Assumptions'!G9+Operasional!G26*'Key Assumptions'!G10)*1000 -> 44695000
A7: Cost of Goods Sold | B7: USD thousands | C7: -25809632 | D7: -29284526 | E7: -32976263 | F7: -36884842 | G7: -41010263
A8: Gross Profit | B8: USD thousands | C8: =C6+C7 -> 2295368.4 | D8: =D6+D7 -> 2618473.7 | E8: =E6+E7 -> 2957736.8 | F8: =F6+F7 -> 3313157.9 | G8: =G6+G7 -> 3684736.8
A9: SG&A | B9: USD thousands | C9: -1000000 | D9: -1100000 | E9: -1200000 | F9: -1300000 | G9: -1400000
A10: EBITDA | B10: USD thousands | C10: =C8+C9 -> 1295368.4 | D10: =D8+D9 -> 1518473.7 | E10: =E8+E9 -> 1757736.8 | F10: =F8+F9 -> 2013157.9 | G10: =G8+G9 -> 2284736.8
A11: DD&A | B11: USD thousands | C11: -500000 | D11: -550000 | E11: -600000 | F11: -650000 | G11: -700000
A12: EBIT (Operating Profit) | B12: USD thousands | C12: =C10+C11 -> 795368.42 | D12: =D10+D11 -> 968473.68 | E12: =E10+E11 -> 1157736.8 | F12: =F10+F11 -> 1363157.9 | G12: =G10+G11 -> 1584736.8
A13: Interest Expense | B13: USD thousands | C13: -100000 | D13: -110000 | E13: -120000 | F13: -130000 | G13: -140000
A14: Earnings Before Taxes | B14: USD thousands | C14: =C12+C13 -> 695368.42 | D14: =D12+D13 -> 858473.68 | E14: =E12+E13 -> 1037736.8 | F14: =F12+F13 -> 1233157.9 | G14: =G12+G13 -> 1444736.8
A15: Taxes | B15: USD thousands | C15: =-C14*$C$3 -> -152981.05 | D15: =-D14*$C$3 -> -188864.21 | E15: =-E14*$C$3 -> -228302.11 | F15: =-F14*$C$3 -> -271294.74 | G15: =-G14*$C$3 -> -317842.11
A16: Net Income | B16: USD thousands | C16: =C14+C15 -> 542387.37 | D16: =D14+D15 -> 669609.47 | E16: =E14+E15 -> 809434.74 | F16: =F14+F15 -> 961863.16 | G16: =G14+G15 -> 1126894.7
A17: EBITDA margin | B17: % | C17: =IF(C6=0,0,C10/C6) -> 0.046090319 | D17: =IF(D6=0,0,D10/D6) -> 0.04759658 | E17: =IF(E6=0,0,E10/E6) -> 0.048915702 | F17: =IF(F6=0,0,F10/F6) -> 0.050081046 | G17: =IF(G6=0,0,G10/G6) -> 0.051118399
A18: Net margin | B18: % | C18: =IF(C6=0,0,C16/C6) -> 0.019298608 | D18: =IF(D6=0,0,D16/D6) -> 0.020988919 | E18: =IF(E6=0,0,E16/E6) -> 0.022525595 | F18: =IF(F6=0,0,F16/F6) -> 0.023928135 | G18: =IF(G6=0,0,G16/G6) -> 0.025212993
A20: Capital Expenditure
A21: CAPEX | B21: USD thousands | C21: 0 | D21: 0 | E21: 0 | F21: 0 | G21: 0

Sheet Data
A1: Data — Flat table of all Hilir RJPP 2026–2030 metrics (Middle Scenario), linked to source sheets
A2: Business Line | B2: Sheet | C2: Section | D2: Metric | E2: Unit | F2: 2026 | G2: 2027 | H2: 2028 | I2: 2029 | J2: 2030
A3: Hilir | B3: Key Assumptions | C3: Price assumptions | D3: Oil Price (crude) | E3: USD/bbl | F3: ='Key Assumptions'!C3 -> 70 | G3: ='Key Assumptions'!D3 -> 75 | H3: ='Key Assumptions'!E3 -> 80 | I3: ='Key Assumptions'!F3 -> 85 | J3: ='Key Assumptions'!G3 -> 90
A4: Hilir | B4: Key Assumptions | C4: Price assumptions | D4: Intermedia + Others | E4: USD/bbl | F4: ='Key Assumptions'!C4 -> 60 | G4: ='Key Assumptions'!D4 -> 65 | H4: ='Key Assumptions'!E4 -> 70 | I4: ='Key Assumptions'!F4 -> 75 | J4: ='Key Assumptions'!G4 -> 80
A5: Hilir | B5: Key Assumptions | C5: Price assumptions | D5: Gasoline | E5: USD/bbl | F5: ='Key Assumptions'!C5 -> 80 | G5: ='Key Assumptions'!D5 -> 86 | H5: ='Key Assumptions'!E5 -> 92 | I5: ='Key Assumptions'!F5 -> 98 | J5: ='Key Assumptions'!G5 -> 104
A6: Hilir | B6: Key Assumptions | C6: Price assumptions | D6: Gasoil | E6: USD/bbl | F6: ='Key Assumptions'!C6 -> 85 | G6: ='Key Assumptions'!D6 -> 92 | H6: ='Key Assumptions'!E6 -> 99 | I6: ='Key Assumptions'!F6 -> 106 | J6: ='Key Assumptions'!G6 -> 113
A7: Hilir | B7: Key Assumptions | C7: Price assumptions | D7: Other Fuel | E7: USD/bbl | F7: ='Key Assumptions'!C7 -> 75 | G7: ='Key Assumptions'!D7 -> 80 | H7: ='Key Assumptions'!E7 -> 85 | I7: ='Key Assumptions'!F7 -> 90 | J7: ='Key Assumptions'!G7 -> 95
A8: Hilir | B8: Key Assumptions | C8: Price assumptions | D8: LPG | E8: USD/bbl | F8: ='Key Assumptions'!C8 -> 70 | G8: ='Key Assumptions'!D8 -> 75 | H8: ='Key Assumptions'!E8 -> 80 | I8: ='Key Assumptions'!F8 -> 85 | J8: ='Key Assumptions'!G8 -> 90
A9: Hilir | B9: Key Assumptions | C9: Price assumptions | D9: Petrokimia | E9: USD/bbl | F9: ='Key Assumptions'!C9 -> 95 | G9: ='Key Assumptions'!D9 -> 100 | H9: ='Key Assumptions'!E9 -> 105 | I9: ='Key Assumptions'!F9 -> 110 | J9: ='Key Assumptions'!G9 -> 115
A10: Hilir | B10: Key Assumptions | C10: Price assumptions | D10: Other Non-Fuel | E10: USD/bbl | F10: ='Key Assumptions'!C10 -> 85 | G10: ='Key Assumptions'!D10 -> 90 | H10: ='Key Assumptions'!E10 -> 95 | I10: ='Key Assumptions'!F10 -> 100 | J10: ='Key Assumptions'!G10 -> 105
A11: Hilir | B11: Key Assumptions | C11: Macro assumptions | D11: Exchange rate USD/IDR | E11: IDR per USD | F11: ='Key Assumptions'!C11 -> 16500 | G11: ='Key Assumptions'!D11 -> 17000 | H11: ='Key Assumptions'!E11 -> 17500 | I11: ='Key Assumptions'!F11 -> 18000 | J11: ='Key Assumptions'!G11 -> 18500
A12: Hilir | B12: Operasional | C12: Refinery input (Input Kilang) | D12: Crude Oil | E12: Juta BBL | F12: =Operasional!C4 -> 326.84211 | G12: =Operasional!D4 -> 345.78947 | H12: =Operasional!E4 -> 364.73684 | I12: =Operasional!F4 -> 383.68421 | J12: =Operasional!G4 -> 402.63158
A13: Hilir | B13: Operasional | C13: Refinery input (Input Kilang) | D13: Intermedia + Others | E13: Juta BBL | F13: =Operasional!C5 -> 36.315789 | G13: =Operasional!D5 -> 38.421053 | H13: =Operasional!E5 -> 40.526316 | I13: =Operasional!F5 -> 42.631579 | J13: =Operasional!G5 -> 44.736842
A14: Hilir | B14: Operasional | C14: Refinery input (Input Kilang) | D14: Total Input Kilang | E14: Juta BBL | F14: =Operasional!C6 -> 363.15789 | G14: =Operasional!D6 -> 384.21053 | H14: =Operasional!E6 -> 405.26316 | I14: =Operasional!F6 -> 426.31579 | J14: =Operasional!G6 -> 447.36842
A15: Hilir | B15: Operasional | C15: Refinery output (Output Kilang) | D15: BBM | E15: Juta BBL | F15: =Operasional!C9 -> 300 | G15: =Operasional!D9 -> 315 | H15: =Operasional!E9 -> 330 | I15: =Operasional!F9 -> 345 | J15: =Operasional!G9 -> 360
A16: Hilir | B16: Operasional | C16: Refinery output (Output Kilang) | D16: LPG | E16: Juta BBL | F16: =Operasional!C10 -> 10 | G16: =Operasional!D10 -> 12 | H16: =Operasional!E10 -> 14 | I16: =Operasional!F10 -> 16 | J16: =Operasional!G10 -> 18
A17: Hilir | B17: Operasional | C17: Refinery output (Output Kilang) | D17: Non-BBM | E17: Juta BBL | F17: =Operasional!C11 -> 35 | G17: =Operasional!D11 -> 38 | H17: =Operasional!E11 -> 41 | I17: =Operasional!F11 -> 44 | J17: =Operasional!G11 -> 47
A18: Hilir | B18: Operasional | C18: Refinery output (Output Kilang) | D18: Total Output Kilang | E18: Juta BBL | F18: =Operasional!C12 -> 345 | G18: =Operasional!D12 -> 365 | H18: =Operasional!E12 -> 385 | I18: =Operasional!F12 -> 405 | J18: =Operasional!G12 -> 425
A19: Hilir | B19: Operasional | C19: Fuel sales (Penjualan BBM) | D19: Gasoline | E19: Juta BBL | F19: =Operasional!C15 -> 150 | G19: =Operasional!D15 -> 157.5 | H19: =Operasional!E15 -> 165 | I19: =Operasional!F15 -> 172.5 | J19: =Operasional!G15 -> 180
A20: Hilir | B20: Operasional | C20: Fuel sales (Penjualan BBM) | D20: Gasoil | E20: Juta BBL | F20: =Operasional!C16 -> 90 | G20: =Operasional!D16 -> 94.5 | H20: =Operasional!E16 -> 99 | I20: =Operasional!F16 -> 103.5 | J20: =Operasional!G16 -> 108
A21: Hilir | B21: Operasional | C21: Fuel sales (Penjualan BBM) | D21: Other Fuel | E21: Juta BBL | F21: =Operasional!C17 -> 60 | G21: =Operasional!D17 -> 63 | H21: =Operasional!E17 -> 66 | I21: =Operasional!F17 -> 69 | J21: =Operasional!G17 -> 72
A22: Hilir | B22: Operasional | C22: Fuel sales (Penjualan BBM) | D22: Total Penjualan BBM | E22: Juta BBL | F22: =Operasional!C18 -> 300 | G22: =Operasional!D18 -> 315 | H22: =Operasional!E18 -> 330 | I22: =Operasional!F18 -> 345 | J22: =Operasional!G18 -> 360
A23: Hilir | B23: Operasional | C23: LPG sales (Penjualan LPG) | D23: LPG | E23: Juta BBL | F23: =Operasional!C21 -> 10 | G23: =Operasional!D21 -> 12 | H23: =Operasional!E21 -> 14 | I23: =Operasional!F21 -> 16 | J23: =Operasional!G21 -> 18
A24: Hilir | B24: Operasional | C24: LPG sales (Penjualan LPG) | D24: Total Penjualan LPG | E24: Juta BBL | F24: =Operasional!C22 -> 10 | G24: =Operasional!D22 -> 12 | H24: =Operasional!E22 -> 14 | I24: =Operasional!F22 -> 16 | J24: =Operasional!G22 -> 18
A25: Hilir | B25: Operasional | C25: Non-fuel sales (Penjualan Non-BBM) | D25: Petrokimia | E25: Juta BBL | F25: =Operasional!C25 -> 28 | G25: =Operasional!D25 -> 30.4 | H25: =Operasional!E25 -> 32.8 | I25: =Operasional!F25 -> 35.2 | J25: =Operasional!G25 -> 37.6
A26: Hilir | B26: Operasional | C26: Non-fuel sales (Penjualan Non-BBM) | D26: Other Non-Fuel | E26: Juta BBL | F26: =Operasional!C26 -> 7 | G26: =Operasional!D26 -> 7.6 | H26: =Operasional!E26 -> 8.2 | I26: =Operasional!F26 -> 8.8 | J26: =Operasional!G26 -> 9.4
A27: Hilir | B27: Operasional | C27: Non-fuel sales (Penjualan Non-BBM) | D27: Total Penjualan Non-BBM | E27: Juta BBL | F27: =Operasional!C27 -> 35 | G27: =Operasional!D27 -> 38 | H27: =Operasional!E27 -> 41 | I27: =Operasional!F27 -> 44 | J27: =Operasional!G27 -> 47
A28: Hilir | B28: Finansial | C28: Assumptions | D28: Corporate tax rate | E28: % | F28: =Finansial!$C$3 -> 0.22 | G28: =Finansial!$C$3 -> 0.22 | H28: =Finansial!$C$3 -> 0.22 | I28: =Finansial!$C$3 -> 0.22 | J28: =Finansial!$C$3 -> 0.22
A29: Hilir | B29: Finansial | C29: Income statement | D29: Revenues | E29: USD thousands | F29: =Finansial!C6 -> 28105000 | G29: =Finansial!D6 -> 31903000 | H29: =Finansial!E6 -> 35934000 | I29: =Finansial!F6 -> 40198000 | J29: =Finansial!G6 -> 44695000
A30: Hilir | B30: Finansial | C30: Income statement | D30: Cost of Goods Sold | E30: USD thousands | F30: =Finansial!C7 -> -25809632 | G30: =Finansial!D7 -> -29284526 | H30: =Finansial!E7 -> -32976263 | I30: =Finansial!F7 -> -36884842 | J30: =Finansial!G7 -> -41010263
A31: Hilir | B31: Finansial | C31: Income statement | D31: Gross Profit | E31: USD thousands | F31: =Finansial!C8 -> 2295368.4 | G31: =Finansial!D8 -> 2618473.7 | H31: =Finansial!E8 -> 2957736.8 | I31: =Finansial!F8 -> 3313157.9 | J31: =Finansial!G8 -> 3684736.8
A32: Hilir | B32: Finansial | C32: Income statement | D32: SG&A | E32: USD thousands | F32: =Finansial!C9 -> -1000000 | G32: =Finansial!D9 -> -1100000 | H32: =Finansial!E9 -> -1200000 | I32: =Finansial!F9 -> -1300000 | J32: =Finansial!G9 -> -1400000
A33: Hilir | B33: Finansial | C33: Income statement | D33: EBITDA | E33: USD thousands | F33: =Finansial!C10 -> 1295368.4 | G33: =Finansial!D10 -> 1518473.7 | H33: =Finansial!E10 -> 1757736.8 | I33: =Finansial!F10 -> 2013157.9 | J33: =Finansial!G10 -> 2284736.8
A34: Hilir | B34: Finansial | C34: Income statement | D34: DD&A | E34: USD thousands | F34: =Finansial!C11 -> -500000 | G34: =Finansial!D11 -> -550000 | H34: =Finansial!E11 -> -600000 | I34: =Finansial!F11 -> -650000 | J34: =Finansial!G11 -> -700000
A35: Hilir | B35: Finansial | C35: Income statement | D35: EBIT (Operating Profit) | E35: USD thousands | F35: =Finansial!C12 -> 795368.42 | G35: =Finansial!D12 -> 968473.68 | H35: =Finansial!E12 -> 1157736.8 | I35: =Finansial!F12 -> 1363157.9 | J35: =Finansial!G12 -> 1584736.8
A36: Hilir | B36: Finansial | C36: Income statement | D36: Interest Expense | E36: USD thousands | F36: =Finansial!C13 -> -100000 | G36: =Finansial!D13 -> -110000 | H36: =Finansial!E13 -> -120000 | I36: =Finansial!F13 -> -130000 | J36: =Finansial!G13 -> -140000
A37: Hilir | B37: Finansial | C37: Income statement | D37: Earnings Before Taxes | E37: USD thousands | F37: =Finansial!C14 -> 695368.42 | G37: =Finansial!D14 -> 858473.68 | H37: =Finansial!E14 -> 1037736.8 | I37: =Finansial!F14 -> 1233157.9 | J37: =Finansial!G14 -> 1444736.8
A38: Hilir | B38: Finansial | C38: Income statement | D38: Taxes | E38: USD thousands | F38: =Finansial!C15 -> -152981.05 | G38: =Finansial!D15 -> -188864.21 | H38: =Finansial!E15 -> -228302.11 | I38: =Finansial!F15 -> -271294.74 | J38: =Finansial!G15 -> -317842.11
A39: Hilir | B39: Finansial | C39: Income statement | D39: Net Income | E39: USD thousands | F39: =Finansial!C16 -> 542387.37 | G39: =Finansial!D16 -> 669609.47 | H39: =Finansial!E16 -> 809434.74 | I39: =Finansial!F16 -> 961863.16 | J39: =Finansial!G16 -> 1126894.7
A40: Hilir | B40: Finansial | C40: Margins | D40: EBITDA margin | E40: % | F40: =Finansial!C17 -> 0.046090319 | G40: =Finansial!D17 -> 0.04759658 | H40: =Finansial!E17 -> 0.048915702 | I40: =Finansial!F17 -> 0.050081046 | J40: =Finansial!G17 -> 0.051118399
...
